<?xml version="1.0"?>
<robot name="mbot" xmlns:xacro="http://www.ros.org/wiki/xacro">

	<!--<xacro:include filename="$(find mbot_pointer)/urdf/mbot.gazebo"/>-->
	<xacro:include filename="$(find mbot_pointer)/urdf/materials.xacro"/>

	<link name = "base_link">
		<visual>
			<geometry>
				<box size = "0.2 0.1 0.1"/>
			</geometry>
			<material name ="blue"/>
		</visual>
		<collision>
			<geometry>
				<box size = "0.2 0.1 0.1"/>
			</geometry>
		</collision>
		<inertial>
			<mass value="1.6"/>
			<inertia ixx="0.00667" ixy="0.0" ixz="0.0" iyy="0.00667" iyz="0.0" izz="0.00267"/>
		</inertial>

		<gazebo reference="base_link">
        	<!--<mu1 value="200.0"/>-->
        	<!--<mu2 value="100.0"/>-->
        	<!--<kp value="10000000.0" />-->
        	<!--<kd value="1.0" />-->
        	<material>Gazebo/Blue</material>
    	</gazebo>
	</link>

	<xacro:macro name="wheel_tran" params="prefix suffix">
		<transmission name="tran_${prefix}_${suffix}">
    		<type>transmission_interface/SimpleTransmission</type>
    		<joint name="base_to_wheel_${prefix}_${suffix}">
      			<hardwareInterface>hardware_interface/VelocityJointInterface</hardwareInterface>
    		</joint>
			<actuator name="motor_${prefix}_${suffix}">
      			<mechanicalReduction>1</mechanicalReduction>
    		</actuator>
  		</transmission>
	</xacro:macro>

	<xacro:macro name="wheel_link" params="prefix suffix xreflect yreflect">
		<link name="wheel_${prefix}_${suffix}">
			<visual>
				<geometry>
					<cylinder length="0.03" radius="0.0245"/>
				</geometry>
				<origin rpy="1.57075 0 0" xyz="0 0 0"/>
				<material name="black"/>
			</visual>
			<collision>
				<geometry>
					<cylinder length="0.03" radius="0.0245"/>
				</geometry>
				<origin rpy="1.57075 0 0" xyz="0 0 0"/>
			</collision>
			<inertial>
				<mass value="0.01"/>
				<inertia ixx="0.00000225" ixy="0.0" ixz="0.0" iyy="0.000003" iyz="0.0" izz="0.00000225"/>
			</inertial>
		</link>
		<joint name="base_to_wheel_${prefix}_${suffix}" type="continuous">
			<axis rpy="0 0 0" xyz="0 1 0"/>
			<parent link="base_link"/>
			<child link="wheel_${prefix}_${suffix}"/>
			<origin rpy="0 0 0" xyz="${xreflect*0.1} ${yreflect*0.065} -0.04"/>
		</joint>
		<gazebo reference="wheel_${prefix}_${suffix}">
			<mu1 value="200.0"/>
        	<mu2 value="100.0"/>
        	<kp value="10000000.0" />
        	<kd value="1.0" />
        	<material>Gazebo/Black</material>
		</gazebo>
		<xacro:wheel_tran prefix="${prefix}" suffix="${suffix}"/>

	</xacro:macro>

	<xacro:wheel_link prefix="front" suffix="left" xreflect="1.0" yreflect="1.0"/>
	<xacro:wheel_link prefix="front" suffix="right" xreflect="1.0" yreflect="-1.0"/>
	<xacro:wheel_link prefix="rear" suffix="left" xreflect="-1.0" yreflect="1.0"/>
	<xacro:wheel_link prefix="rear" suffix="right" xreflect="-1.0" yreflect="-1.0"/>

    <link name="imu">
        <visual>
            <geometry>
                <box size="0.001 0.001 0.0001"/>
            </geometry>
            <material name="grey"/>
        </visual>
		<inertial>
			<mass value="0.01"/>
			<inertia ixx="0.000001" ixy="0.0" ixz="0.0" iyy="0.000001" iyz="0.0" izz="0.0000001"/>
		</inertial>
		<gazebo reference="imu">
			<material>Gazebo/Grey</material>
		</gazebo>
    </link>
    <joint name="base_ot_imu" type="fixed">
        <parent link="base_link"/>
        <child link="imu"/>
        <origin rpy="0 0 0" xyz="0 0 0.05"/>
    </joint>

    <link name="xtion">
        <visual>
            <geometry>
                <box size="0.05 0.18 0.03"/>
            </geometry>
            <material name="green"/>
        </visual>
		<inertial>
			<mass value="0.1"/>
			<inertia ixx="0.0000283" ixy="0.0" ixz="0.0" iyy="0.0002775" iyz="0.0" izz="0.00029"/>
		</inertial>
		<gazebo reference="xtion">
			<material>Gazebo/Green</material>
		</gazebo>
    </link>
    <joint name="base_to_xtion" type="fixed">
        <parent link="base_link"/>
        <child link="xtion"/>
        <origin rpy="0 0 0" xyz="0.068 0 0.065"/>
    </joint>

	<gazebo>
        <plugin name="gazebo_ros_control" filename="libgazebo_ros_control.so">
            <robotNamespace>/</robotNamespace>
            <robotSimType>gazebo_ros_control/DefaultRobotHWSim</robotSimType>
        </plugin>
    </gazebo>

</robot>